Workbook

Sheet 00_Cover
A1: IDINO Agent Hub — 전수 화면 체크리스트 (트랙 #83)
A3: 작업 트랙 | B3: #83 — 전수 화면 체크리스트 + 라이브 e2e
A4: 작성일 | B4: 2026-05-12
A5: 대상 시스템 | B5: AgentHub Vue 3 (49 routes) + DocUtil Next.js 16 (25 routes)
A6: 운영 URL | B6: AgentHub: http://192.168.10.39:64005 | DocUtil: http://192.168.10.39:8041
A7: 총 케이스 수 | B7: 479
A8: 총 시트 수 | B8: 83 (Cover/Summary 포함)
A9: 운영 영향 정책 | B9: read-only 진입 + 안전 mutation 1 cycle (시나리오 1 인용) 만
A10: LLM 비용 정책 | B10: Playground/이미지/PPTX 등은 폼 표시만 — 전송 안 함. 채팅 1회는 시나리오 2 인용
A11: DocUtil 자격증명 | B11: 미확보 — DocUtil 사용자/관리자 페이지는 SKIP. 자격증명 제공 시 진행 분기
A12: 관련 commit | B12: 트랙 #75: b7de919 / 3542e33 (시나리오 1~4)

Sheet 01_Summary
A1: 집계
A3: 시트 | B3: 케이스 수 | C3: PASS | D3: FAIL | E3: SKIP | F3: 미실행
A4: ALL | B4: 2 | C4: =COUNTIF('ALL'!I:I,"PASS") | D4: =COUNTIF('ALL'!I:I,"FAIL") | E4: =COUNTIF('ALL'!I:I,"SKIP") | F4: =B4-C4-D4-E4
A5: AdminDocUtilApiKeys | B5: 7 | C5: =COUNTIF('AdminDocUtilApiKeys'!I:I,"PASS") | D5: =COUNTIF('AdminDocUtilApiKeys'!I:I,"FAIL") | E5: =COUNTIF('AdminDocUtilApiKeys'!I:I,"SKIP") | F5: =B5-C5-D5-E5
A6: AdminDocUtilAudit | B6: 7 | C6: =COUNTIF('AdminDocUtilAudit'!I:I,"PASS") | D6: =COUNTIF('AdminDocUtilAudit'!I:I,"FAIL") | E6: =COUNTIF('AdminDocUtilAudit'!I:I,"SKIP") | F6: =B6-C6-D6-E6
A7: AdminDocUtilDashboard | B7: 7 | C7: =COUNTIF('AdminDocUtilDashboard'!I:I,"PASS") | D7: =COUNTIF('AdminDocUtilDashboard'!I:I,"FAIL") | E7: =COUNTIF('AdminDocUtilDashboard'!I:I,"SKIP") | F7: =B7-C7-D7-E7
A8: AdminDocUtilDepartments | B8: 7 | C8: =COUNTIF('AdminDocUtilDepartments'!I:I,"PASS") | D8: =COUNTIF('AdminDocUtilDepartments'!I:I,"FAIL") | E8: =COUNTIF('AdminDocUtilDepartments'!I:I,"SKIP") | F8: =B8-C8-D8-E8
A9: AdminDocUtilDocAgents | B9: 7 | C9: =COUNTIF('AdminDocUtilDocAgents'!I:I,"PASS") | D9: =COUNTIF('AdminDocUtilDocAgents'!I:I,"FAIL") | E9: =COUNTIF('AdminDocUtilDocAgents'!I:I,"SKIP") | F9: =B9-C9-D9-E9
A10: AdminDocUtilDocumentsV2 | B10: 7 | C10: =COUNTIF('AdminDocUtilDocumentsV2'!I:I,"PASS") | D10: =COUNTIF('AdminDocUtilDocumentsV2'!I:I,"FAIL") | E10: =COUNTIF('AdminDocUtilDocumentsV2'!I:I,"SKIP") | F10: =B10-C10-D10-E10
A11: AdminDocUtilEvaluation | B11: 7 | C11: =COUNTIF('AdminDocUtilEvaluation'!I:I,"PASS") | D11: =COUNTIF('AdminDocUtilEvaluation'!I:I,"FAIL") | E11: =COUNTIF('AdminDocUtilEvaluation'!I:I,"SKIP") | F11: =B11-C11-D11-E11
A12: AdminDocUtilFaq | B12: 7 | C12: =COUNTIF('AdminDocUtilFaq'!I:I,"PASS") | D12: =COUNTIF('AdminDocUtilFaq'!I:I,"FAIL") | E12: =COUNTIF('AdminDocUtilFaq'!I:I,"SKIP") | F12: =B12-C12-D12-E12
A13: AdminDocUtilProjects | B13: 7 | C13: =COUNTIF('AdminDocUtilProjects'!I:I,"PASS") | D13: =COUNTIF('AdminDocUtilProjects'!I:I,"FAIL") | E13: =COUNTIF('AdminDocUtilProjects'!I:I,"SKIP") | F13: =B13-C13-D13-E13
A14: AdminDocUtilReports | B14: 7 | C14: =COUNTIF('AdminDocUtilReports'!I:I,"PASS") | D14: =COUNTIF('AdminDocUtilReports'!I:I,"FAIL") | E14: =COUNTIF('AdminDocUtilReports'!I:I,"SKIP") | F14: =B14-C14-D14-E14
A15: AdminDocUtilSearchScopes | B15: 7 | C15: =COUNTIF('AdminDocUtilSearchScopes'!I:I,"PASS") | D15: =COUNTIF('AdminDocUtilSearchScopes'!I:I,"FAIL") | E15: =COUNTIF('AdminDocUtilSearchScopes'!I:I,"SKIP") | F15: =B15-C15-D15-E15
A16: AdminDocUtilTemplates | B16: 7 | C16: =COUNTIF('AdminDocUtilTemplates'!I:I,"PASS") | D16: =COUNTIF('AdminDocUtilTemplates'!I:I,"FAIL") | E16: =COUNTIF('AdminDocUtilTemplates'!I:I,"SKIP") | F16: =B16-C16-D16-E16
A17: AdminDocUtilUsers | B17: 7 | C17: =COUNTIF('AdminDocUtilUsers'!I:I,"PASS") | D17: =COUNTIF('AdminDocUtilUsers'!I:I,"FAIL") | E17: =COUNTIF('AdminDocUtilUsers'!I:I,"SKIP") | F17: =B17-C17-D17-E17
A18: AdminKnowledgeBase | B18: 7 | C18: =COUNTIF('AdminKnowledgeBase'!I:I,"PASS") | D18: =COUNTIF('AdminKnowledgeBase'!I:I,"FAIL") | E18: =COUNTIF('AdminKnowledgeBase'!I:I,"SKIP") | F18: =B18-C18-D18-E18
A19: AdminKnowledgeBaseUpload | B19: 6 | C19: =COUNTIF('AdminKnowledgeBaseUpload'!I:I,"PASS") | D19: =COUNTIF('AdminKnowledgeBaseUpload'!I:I,"FAIL") | E19: =COUNTIF('AdminKnowledgeBaseUpload'!I:I,"SKIP") | F19: =B19-C19-D19-E19
A20: AdminRagMetrics | B20: 7 | C20: =COUNTIF('AdminRagMetrics'!I:I,"PASS") | D20: =COUNTIF('AdminRagMetrics'!I:I,"FAIL") | E20: =COUNTIF('AdminRagMetrics'!I:I,"SKIP") | F20: =B20-C20-D20-E20
A21: AgentBuilder | B21: 7 | C21: =COUNTIF('AgentBuilder'!I:I,"PASS") | D21: =COUNTIF('AgentBuilder'!I:I,"FAIL") | E21: =COUNTIF('AgentBuilder'!I:I,"SKIP") | F21: =B21-C21-D21-E21
A22: AgentChat | B22: 7 | C22: =COUNTIF('AgentChat'!I:I,"PASS") | D22: =COUNTIF('AgentChat'!I:I,"FAIL") | E22: =COUNTIF('AgentChat'!I:I,"SKIP") | F22: =B22-C22-D22-E22
A23: AgentEmbed | B23: 5 | C23: =COUNTIF('AgentEmbed'!I:I,"PASS") | D23: =COUNTIF('AgentEmbed'!I:I,"FAIL") | E23: =COUNTIF('AgentEmbed'!I:I,"SKIP") | F23: =B23-C23-D23-E23
A24: AgentMarketplace | B24: 7 | C24: =COUNTIF('AgentMarketplace'!I:I,"PASS") | D24: =COUNTIF('AgentMarketplace'!I:I,"FAIL") | E24: =COUNTIF('AgentMarketplace'!I:I,"SKIP") | F24: =B24-C24-D24-E24
A25: AgentMultiChat | B25: 7 | C25: =COUNTIF('AgentMultiChat'!I:I,"PASS") | D25: =COUNTIF('AgentMultiChat'!I:I,"FAIL") | E25: =COUNTIF('AgentMultiChat'!I:I,"SKIP") | F25: =B25-C25-D25-E25
A26: AgentPublicChat | B26: 5 | C26: =COUNTIF('AgentPublicChat'!I:I,"PASS") | D26: =COUNTIF('AgentPublicChat'!I:I,"FAIL") | E26: =COUNTIF('AgentPublicChat'!I:I,"SKIP") | F26: =B26-C26-D26-E26
A27: AgentTemplates | B27: 7 | C27: =COUNTIF('AgentTemplates'!I:I,"PASS") | D27: =COUNTIF('AgentTemplates'!I:I,"FAIL") | E27: =COUNTIF('AgentTemplates'!I:I,"SKIP") | F27: =B27-C27-D27-E27
A28: AgentTestPage | B28: 4 | C28: =COUNTIF('AgentTestPage'!I:I,"PASS") | D28: =COUNTIF('AgentTestPage'!I:I,"FAIL") | E28: =COUNTIF('AgentTestPage'!I:I,"SKIP") | F28: =B28-C28-D28-E28
A29: Agents | B29: 7 | C29: =COUNTIF('Agents'!I:I,"PASS") | D29: =COUNTIF('Agents'!I:I,"FAIL") | E29: =COUNTIF('Agents'!I:I,"SKIP") | F29: =B29-C29-D29-E29
A30: Analytics | B30: 7 | C30: =COUNTIF('Analytics'!I:I,"PASS") | D30: =COUNTIF('Analytics'!I:I,"FAIL") | E30: =COUNTIF('Analytics'!I:I,"SKIP") | F30: =B30-C30-D30-E30
A31: ApiKeys | B31: 8 | C31: =COUNTIF('ApiKeys'!I:I,"PASS") | D31: =COUNTIF('ApiKeys'!I:I,"FAIL") | E31: =COUNTIF('ApiKeys'!I:I,"SKIP") | F31: =B31-C31-D31-E31
A32: AuditLog | B32: 7 | C32: =COUNTIF('AuditLog'!I:I,"PASS") | D32: =COUNTIF('AuditLog'!I:I,"FAIL") | E32: =COUNTIF('AuditLog'!I:I,"SKIP") | F32: =B32-C32-D32-E32
A33: BannedWords | B33: 7 | C33: =COUNTIF('BannedWords'!I:I,"PASS") | D33: =COUNTIF('BannedWords'!I:I,"FAIL") | E33: =COUNTIF('BannedWords'!I:I,"SKIP") | F33: =B33-C33-D33-E33
A34: CostAnalysis | B34: 7 | C34: =COUNTIF('CostAnalysis'!I:I,"PASS") | D34: =COUNTIF('CostAnalysis'!I:I,"FAIL") | E34: =COUNTIF('CostAnalysis'!I:I,"SKIP") | F34: =B34-C34-D34-E34
A35: DU_AdminAccounts | B35: 4 | C35: =COUNTIF('DU_AdminAccounts'!I:I,"PASS") | D35: =COUNTIF('DU_AdminAccounts'!I:I,"FAIL") | E35: =COUNTIF('DU_AdminAccounts'!I:I,"SKIP") | F35: =B35-C35-D35-E35
A36: DU_AdminDashboard | B36: 4 | C36: =COUNTIF('DU_AdminDashboard'!I:I,"PASS") | D36: =COUNTIF('DU_AdminDashboard'!I:I,"FAIL") | E36: =COUNTIF('DU_AdminDashboard'!I:I,"SKIP") | F36: =B36-C36-D36-E36
A37: DU_Agents | B37: 4 | C37: =COUNTIF('DU_Agents'!I:I,"PASS") | D37: =COUNTIF('DU_Agents'!I:I,"FAIL") | E37: =COUNTIF('DU_Agents'!I:I,"SKIP") | F37: =B37-C37-D37-E37
A38: DU_ApiKeys | B38: 4 | C38: =COUNTIF('DU_ApiKeys'!I:I,"PASS") | D38: =COUNTIF('DU_ApiKeys'!I:I,"FAIL") | E38: =COUNTIF('DU_ApiKeys'!I:I,"SKIP") | F38: =B38-C38-D38-E38
A39: DU_Chat | B39: 4 | C39: =COUNTIF('DU_Chat'!I:I,"PASS") | D39: =COUNTIF('DU_Chat'!I:I,"FAIL") | E39: =COUNTIF('DU_Chat'!I:I,"SKIP") | F39: =B39-C39-D39-E39
A40: DU_Departments | B40: 4 | C40: =COUNTIF('DU_Departments'!I:I,"PASS") | D40: =COUNTIF('DU_Departments'!I:I,"FAIL") | E40: =COUNTIF('DU_Departments'!I:I,"SKIP") | F40: =B40-C40-D40-E40
A41: DU_DesignerCreate | B41: 4 | C41: =COUNTIF('DU_DesignerCreate'!I:I,"PASS") | D41: =COUNTIF('DU_DesignerCreate'!I:I,"FAIL") | E41: =COUNTIF('DU_DesignerCreate'!I:I,"SKIP") | F41: =B41-C41-D41-E41
...

Sheet ALL
A1: ID | B1: 화면 | C1: 인터랙션 | D1: 사전조건 | E1: 입력/액션 | F1: 기대 결과 | G1: 위험도 | H1: 자동화 | I1: 결과 | J1: 실측값 | K1: 비고 | L1: 검증일시 | M1: 스크린샷 경로
A2: AH-SP-130 | B2: 전역 — DocUtil 502 fallback | C2: [시나리오 3 인용] AdminDocUtil* 13개 화면에서 DocUtil 502 시 한국어 에러 fallback | D2: 트랙 #75 commit b7de919 참조 | E2: (자동화 완료 — 재실행 안 함) | F2: PASS (시나리오 3 결과 인용) | G2: safe | H2: manual | I2: PASS | K2: [시나리오 3 인용] tools/ui_e2e/scenario_3_result.json (b7de919) | L2: 2026-05-12 (인용)
A3: AH-SP-131 | B3: 전역 — DocUtil 로그인 확인 | C3: [시나리오 4 인용] DocUtil 자격증명 미확보 확인 | D3: 트랙 #75 commit 3542e33 참조 | E3: (자동화 완료 — 재실행 안 함) | F3: SKIP (시나리오 4 결과 인용 — DocUtil 자격증명 제공 시 진행) | G3: safe | H3: manual | I3: SKIP | K3: [시나리오 4 인용] tools/ui_e2e/scenario_4_result.json (3542e33) | L3: 2026-05-12 (인용)

Sheet AdminDocUtilApiKeys
A1: ID | B1: 화면 | C1: 인터랙션 | D1: 사전조건 | E1: 입력/액션 | F1: 기대 결과 | G1: 위험도 | H1: 자동화 | I1: 결과 | J1: 실측값 | K1: 비고 | L1: 검증일시 | M1: 스크린샷 경로
A2: AH-038-01 | B2: AdminDocUtilApiKeys | C2: 화면 진입 (admin 세션) | D2: (admin 로그인) — public 라우트도 admin 세션 보유 상태에서 진입 | E2: GET /admin/docutil-api-keys | F2: HTTP 200 또는 클라이언트 라우팅 성공 + 페이지 마운트 (Vue/Next 컴포넌트 렌더) | G2: safe | H2: auto | I2: PASS | J2: DOM mounted=True | duration=1785ms | final=http://192.168.10.39:64005/admin/docutil-api-keys | L2: 2026-05-12 15:33:17 | M2: tools/ui_e2e/screenshots/full/AH_PROT_AdminDocUtilApiKeys.png
A3: AH-038-02 | B3: AdminDocUtilApiKeys | C3: 권한 분기 (anonymous → /login 리다이렉트) | D3: (미로그인 + 새 컨텍스트) | E3: GET /admin/docutil-api-keys (token 없음) | F3: /login?redirect=... 또는 /landing 으로 리다이렉트 | G3: safe | H3: auto | I3: PASS | J3: final=http://192.168.10.39:64005/login?redirect=/admin/docutil-api-keys | K3: final=http://192.168.10.39:64005/login?redirect=/admin/docutil-api-keys | L3: 2026-05-12 15:40:00
A4: AH-038-03 | B4: AdminDocUtilApiKeys | C4: DOM 마운트 + 주요 컨테이너 렌더 | D4: (라우트 진입 완료) | E4: DOM 로드 + 1초 대기 → console error 0건 + 핵심 selector 가시 | F4: console error 0건 (잘 알려진 외부 라이브러리 경고 제외), 핵심 컨테이너(main/main-layout/page-root) 렌더 | G4: safe | H4: auto | I4: PASS | L4: 2026-05-12 15:33:17
A5: AH-038-04 | B5: AdminDocUtilApiKeys | C5: 페이지 진입 시 API 자동 호출 응답 확인 | D5: (라우트 진입 완료) | E5: network 모니터 — 첫 5초 내 발생한 /api 또는 /v1 호출 + 상태코드 수집 | F5: 관련 API 200 OK 또는 비-401 응답. 401 발생 시 권한 분기 케이스로 분류 | G5: safe | H5: auto | I5: PASS | L5: 2026-05-12 15:33:17
A6: AH-038-05 | B6: AdminDocUtilApiKeys | C6: 사이드바 / 헤더 / 활성 메뉴 표시 | D6: (라우트 진입 완료) | E6: 선택된 메뉴 highlight + 현재 사용자(admin) 정보 표시 확인 | F6: 사이드바 노드 활성 클래스 + 사용자 아바타/이름 가시 | G6: safe | H6: auto | I6: PASS | L6: 2026-05-12 15:33:17
A7: AH-038-06 | B7: AdminDocUtilApiKeys | C7: 스크린샷 캡처 (감사용) | D7: (라우트 진입 + DOM 안정화) | E7: viewport 스크린샷 (full=false) | F7: screenshots/full/ 하위 .png 저장됨 (평문 시크릿 없음) | G7: safe | H7: auto | I7: PASS | L7: 2026-05-12 15:33:17 | M7: tools/ui_e2e/screenshots/full/AH_PROT_AdminDocUtilApiKeys.png
A8: AH-SP-050-docutil-api-keys | B8: DocUtil API 키 | C8: BFF 데이터 로드 (DocUtil → AgentHub BFF) | D8: (admin 로그인) | E8: /admin/docutil-api-keys 진입 | F8: DocUtil API 응답 또는 5xx 시 한국어 에러 토스트 | G8: safe | H8: auto | I8: PASS | K8: [라이브 라우트 결과 인용] AdminDocUtilApiKeys: PASS | L8: 2026-05-12 (인용)

Sheet AdminDocUtilAudit
A1: ID | B1: 화면 | C1: 인터랙션 | D1: 사전조건 | E1: 입력/액션 | F1: 기대 결과 | G1: 위험도 | H1: 자동화 | I1: 결과 | J1: 실측값 | K1: 비고 | L1: 검증일시 | M1: 스크린샷 경로
A2: AH-032-01 | B2: AdminDocUtilAudit | C2: 화면 진입 (admin 세션) | D2: (admin 로그인) — public 라우트도 admin 세션 보유 상태에서 진입 | E2: GET /admin/docutil-audit | F2: HTTP 200 또는 클라이언트 라우팅 성공 + 페이지 마운트 (Vue/Next 컴포넌트 렌더) | G2: safe | H2: auto | I2: PASS | J2: DOM mounted=True | duration=1796ms | final=http://192.168.10.39:64005/admin/docutil-audit | L2: 2026-05-12 15:33:06 | M2: tools/ui_e2e/screenshots/full/AH_PROT_AdminDocUtilAudit.png
A3: AH-032-02 | B3: AdminDocUtilAudit | C3: 권한 분기 (anonymous → /login 리다이렉트) | D3: (미로그인 + 새 컨텍스트) | E3: GET /admin/docutil-audit (token 없음) | F3: /login?redirect=... 또는 /landing 으로 리다이렉트 | G3: safe | H3: auto | I3: PASS | J3: final=http://192.168.10.39:64005/login?redirect=/admin/docutil-audit | K3: final=http://192.168.10.39:64005/login?redirect=/admin/docutil-audit | L3: 2026-05-12 15:40:00
A4: AH-032-03 | B4: AdminDocUtilAudit | C4: DOM 마운트 + 주요 컨테이너 렌더 | D4: (라우트 진입 완료) | E4: DOM 로드 + 1초 대기 → console error 0건 + 핵심 selector 가시 | F4: console error 0건 (잘 알려진 외부 라이브러리 경고 제외), 핵심 컨테이너(main/main-layout/page-root) 렌더 | G4: safe | H4: auto | I4: PASS | L4: 2026-05-12 15:33:06
A5: AH-032-04 | B5: AdminDocUtilAudit | C5: 페이지 진입 시 API 자동 호출 응답 확인 | D5: (라우트 진입 완료) | E5: network 모니터 — 첫 5초 내 발생한 /api 또는 /v1 호출 + 상태코드 수집 | F5: 관련 API 200 OK 또는 비-401 응답. 401 발생 시 권한 분기 케이스로 분류 | G5: safe | H5: auto | I5: PASS | L5: 2026-05-12 15:33:06
A6: AH-032-05 | B6: AdminDocUtilAudit | C6: 사이드바 / 헤더 / 활성 메뉴 표시 | D6: (라우트 진입 완료) | E6: 선택된 메뉴 highlight + 현재 사용자(admin) 정보 표시 확인 | F6: 사이드바 노드 활성 클래스 + 사용자 아바타/이름 가시 | G6: safe | H6: auto | I6: PASS | L6: 2026-05-12 15:33:06
A7: AH-032-06 | B7: AdminDocUtilAudit | C7: 스크린샷 캡처 (감사용) | D7: (라우트 진입 + DOM 안정화) | E7: viewport 스크린샷 (full=false) | F7: screenshots/full/ 하위 .png 저장됨 (평문 시크릿 없음) | G7: safe | H7: auto | I7: PASS | L7: 2026-05-12 15:33:06 | M7: tools/ui_e2e/screenshots/full/AH_PROT_AdminDocUtilAudit.png
A8: AH-SP-050-docutil-audit | B8: DocUtil 감사 | C8: BFF 데이터 로드 (DocUtil → AgentHub BFF) | D8: (admin 로그인) | E8: /admin/docutil-audit 진입 | F8: DocUtil API 응답 또는 5xx 시 한국어 에러 토스트 | G8: safe | H8: auto | I8: PASS | K8: [라이브 라우트 결과 인용] AdminDocUtilAudit: PASS | L8: 2026-05-12 (인용)

Sheet AdminDocUtilDashboard
A1: ID | B1: 화면 | C1: 인터랙션 | D1: 사전조건 | E1: 입력/액션 | F1: 기대 결과 | G1: 위험도 | H1: 자동화 | I1: 결과 | J1: 실측값 | K1: 비고 | L1: 검증일시 | M1: 스크린샷 경로
A2: AH-031-01 | B2: AdminDocUtilDashboard | C2: 화면 진입 (admin 세션) | D2: (admin 로그인) — public 라우트도 admin 세션 보유 상태에서 진입 | E2: GET /admin/docutil-dashboard | F2: HTTP 200 또는 클라이언트 라우팅 성공 + 페이지 마운트 (Vue/Next 컴포넌트 렌더) | G2: safe | H2: auto | I2: PASS | J2: DOM mounted=True | duration=1786ms | final=http://192.168.10.39:64005/admin/docutil-dashboard | L2: 2026-05-12 15:33:04 | M2: tools/ui_e2e/screenshots/full/AH_PROT_AdminDocUtilDashboard.png
A3: AH-031-02 | B3: AdminDocUtilDashboard | C3: 권한 분기 (anonymous → /login 리다이렉트) | D3: (미로그인 + 새 컨텍스트) | E3: GET /admin/docutil-dashboard (token 없음) | F3: /login?redirect=... 또는 /landing 으로 리다이렉트 | G3: safe | H3: auto | I3: PASS | J3: final=http://192.168.10.39:64005/login?redirect=/admin/docutil-dashboard | K3: final=http://192.168.10.39:64005/login?redirect=/admin/docutil-dashboard | L3: 2026-05-12 15:40:00
A4: AH-031-03 | B4: AdminDocUtilDashboard | C4: DOM 마운트 + 주요 컨테이너 렌더 | D4: (라우트 진입 완료) | E4: DOM 로드 + 1초 대기 → console error 0건 + 핵심 selector 가시 | F4: console error 0건 (잘 알려진 외부 라이브러리 경고 제외), 핵심 컨테이너(main/main-layout/page-root) 렌더 | G4: safe | H4: auto | I4: PASS | L4: 2026-05-12 15:33:04
A5: AH-031-04 | B5: AdminDocUtilDashboard | C5: 페이지 진입 시 API 자동 호출 응답 확인 | D5: (라우트 진입 완료) | E5: network 모니터 — 첫 5초 내 발생한 /api 또는 /v1 호출 + 상태코드 수집 | F5: 관련 API 200 OK 또는 비-401 응답. 401 발생 시 권한 분기 케이스로 분류 | G5: safe | H5: auto | I5: PASS | L5: 2026-05-12 15:33:04
A6: AH-031-05 | B6: AdminDocUtilDashboard | C6: 사이드바 / 헤더 / 활성 메뉴 표시 | D6: (라우트 진입 완료) | E6: 선택된 메뉴 highlight + 현재 사용자(admin) 정보 표시 확인 | F6: 사이드바 노드 활성 클래스 + 사용자 아바타/이름 가시 | G6: safe | H6: auto | I6: PASS | L6: 2026-05-12 15:33:04
A7: AH-031-06 | B7: AdminDocUtilDashboard | C7: 스크린샷 캡처 (감사용) | D7: (라우트 진입 + DOM 안정화) | E7: viewport 스크린샷 (full=false) | F7: screenshots/full/ 하위 .png 저장됨 (평문 시크릿 없음) | G7: safe | H7: auto | I7: PASS | L7: 2026-05-12 15:33:04 | M7: tools/ui_e2e/screenshots/full/AH_PROT_AdminDocUtilDashboard.png
A8: AH-SP-050-docutil-dashboard | B8: DocUtil 대시보드 | C8: BFF 데이터 로드 (DocUtil → AgentHub BFF) | D8: (admin 로그인) | E8: /admin/docutil-dashboard 진입 | F8: DocUtil API 응답 또는 5xx 시 한국어 에러 토스트 | G8: safe | H8: auto | I8: PASS | K8: [라이브 라우트 결과 인용] AdminDocUtilDashboard: PASS | L8: 2026-05-12 (인용)

Sheet AdminDocUtilDepartments
A1: ID | B1: 화면 | C1: 인터랙션 | D1: 사전조건 | E1: 입력/액션 | F1: 기대 결과 | G1: 위험도 | H1: 자동화 | I1: 결과 | J1: 실측값 | K1: 비고 | L1: 검증일시 | M1: 스크린샷 경로
A2: AH-029-01 | B2: AdminDocUtilDepartments | C2: 화면 진입 (admin 세션) | D2: (admin 로그인) — public 라우트도 admin 세션 보유 상태에서 진입 | E2: GET /admin/docutil-departments | F2: HTTP 200 또는 클라이언트 라우팅 성공 + 페이지 마운트 (Vue/Next 컴포넌트 렌더) | G2: safe | H2: auto | I2: PASS | J2: DOM mounted=True | duration=1780ms | final=http://192.168.10.39:64005/admin/docutil-departments | L2: 2026-05-12 15:33:01 | M2: tools/ui_e2e/screenshots/full/AH_PROT_AdminDocUtilDepartments.png
A3: AH-029-02 | B3: AdminDocUtilDepartments | C3: 권한 분기 (anonymous → /login 리다이렉트) | D3: (미로그인 + 새 컨텍스트) | E3: GET /admin/docutil-departments (token 없음) | F3: /login?redirect=... 또는 /landing 으로 리다이렉트 | G3: safe | H3: auto | I3: PASS | J3: final=http://192.168.10.39:64005/login?redirect=/admin/docutil-departments | K3: final=http://192.168.10.39:64005/login?redirect=/admin/docutil-departments | L3: 2026-05-12 15:40:00
A4: AH-029-03 | B4: AdminDocUtilDepartments | C4: DOM 마운트 + 주요 컨테이너 렌더 | D4: (라우트 진입 완료) | E4: DOM 로드 + 1초 대기 → console error 0건 + 핵심 selector 가시 | F4: console error 0건 (잘 알려진 외부 라이브러리 경고 제외), 핵심 컨테이너(main/main-layout/page-root) 렌더 | G4: safe | H4: auto | I4: PASS | L4: 2026-05-12 15:33:01
A5: AH-029-04 | B5: AdminDocUtilDepartments | C5: 페이지 진입 시 API 자동 호출 응답 확인 | D5: (라우트 진입 완료) | E5: network 모니터 — 첫 5초 내 발생한 /api 또는 /v1 호출 + 상태코드 수집 | F5: 관련 API 200 OK 또는 비-401 응답. 401 발생 시 권한 분기 케이스로 분류 | G5: safe | H5: auto | I5: PASS | L5: 2026-05-12 15:33:01
A6: AH-029-05 | B6: AdminDocUtilDepartments | C6: 사이드바 / 헤더 / 활성 메뉴 표시 | D6: (라우트 진입 완료) | E6: 선택된 메뉴 highlight + 현재 사용자(admin) 정보 표시 확인 | F6: 사이드바 노드 활성 클래스 + 사용자 아바타/이름 가시 | G6: safe | H6: auto | I6: PASS | L6: 2026-05-12 15:33:01
A7: AH-029-06 | B7: AdminDocUtilDepartments | C7: 스크린샷 캡처 (감사용) | D7: (라우트 진입 + DOM 안정화) | E7: viewport 스크린샷 (full=false) | F7: screenshots/full/ 하위 .png 저장됨 (평문 시크릿 없음) | G7: safe | H7: auto | I7: PASS | L7: 2026-05-12 15:33:01 | M7: tools/ui_e2e/screenshots/full/AH_PROT_AdminDocUtilDepartments.png
A8: AH-SP-050-docutil-departments | B8: DocUtil 부서 | C8: BFF 데이터 로드 (DocUtil → AgentHub BFF) | D8: (admin 로그인) | E8: /admin/docutil-departments 진입 | F8: DocUtil API 응답 또는 5xx 시 한국어 에러 토스트 | G8: safe | H8: auto | I8: PASS | K8: [라이브 라우트 결과 인용] AdminDocUtilDepartments: PASS | L8: 2026-05-12 (인용)

Sheet AdminDocUtilDocAgents
A1: ID | B1: 화면 | C1: 인터랙션 | D1: 사전조건 | E1: 입력/액션 | F1: 기대 결과 | G1: 위험도 | H1: 자동화 | I1: 결과 | J1: 실측값 | K1: 비고 | L1: 검증일시 | M1: 스크린샷 경로
A2: AH-039-01 | B2: AdminDocUtilDocAgents | C2: 화면 진입 (admin 세션) | D2: (admin 로그인) — public 라우트도 admin 세션 보유 상태에서 진입 | E2: GET /admin/docutil-doc-agents | F2: HTTP 200 또는 클라이언트 라우팅 성공 + 페이지 마운트 (Vue/Next 컴포넌트 렌더) | G2: safe | H2: auto | I2: PASS | J2: DOM mounted=True | duration=1796ms | final=http://192.168.10.39:64005/admin/docutil-doc-agents | L2: 2026-05-12 15:33:19 | M2: tools/ui_e2e/screenshots/full/AH_PROT_AdminDocUtilDocAgents.png
A3: AH-039-02 | B3: AdminDocUtilDocAgents | C3: 권한 분기 (anonymous → /login 리다이렉트) | D3: (미로그인 + 새 컨텍스트) | E3: GET /admin/docutil-doc-agents (token 없음) | F3: /login?redirect=... 또는 /landing 으로 리다이렉트 | G3: safe | H3: auto | I3: PASS | J3: final=http://192.168.10.39:64005/login?redirect=/admin/docutil-doc-agents | K3: final=http://192.168.10.39:64005/login?redirect=/admin/docutil-doc-agents | L3: 2026-05-12 15:40:00
A4: AH-039-03 | B4: AdminDocUtilDocAgents | C4: DOM 마운트 + 주요 컨테이너 렌더 | D4: (라우트 진입 완료) | E4: DOM 로드 + 1초 대기 → console error 0건 + 핵심 selector 가시 | F4: console error 0건 (잘 알려진 외부 라이브러리 경고 제외), 핵심 컨테이너(main/main-layout/page-root) 렌더 | G4: safe | H4: auto | I4: PASS | L4: 2026-05-12 15:33:19
A5: AH-039-04 | B5: AdminDocUtilDocAgents | C5: 페이지 진입 시 API 자동 호출 응답 확인 | D5: (라우트 진입 완료) | E5: network 모니터 — 첫 5초 내 발생한 /api 또는 /v1 호출 + 상태코드 수집 | F5: 관련 API 200 OK 또는 비-401 응답. 401 발생 시 권한 분기 케이스로 분류 | G5: safe | H5: auto | I5: PASS | L5: 2026-05-12 15:33:19
A6: AH-039-05 | B6: AdminDocUtilDocAgents | C6: 사이드바 / 헤더 / 활성 메뉴 표시 | D6: (라우트 진입 완료) | E6: 선택된 메뉴 highlight + 현재 사용자(admin) 정보 표시 확인 | F6: 사이드바 노드 활성 클래스 + 사용자 아바타/이름 가시 | G6: safe | H6: auto | I6: PASS | L6: 2026-05-12 15:33:19
A7: AH-039-06 | B7: AdminDocUtilDocAgents | C7: 스크린샷 캡처 (감사용) | D7: (라우트 진입 + DOM 안정화) | E7: viewport 스크린샷 (full=false) | F7: screenshots/full/ 하위 .png 저장됨 (평문 시크릿 없음) | G7: safe | H7: auto | I7: PASS | L7: 2026-05-12 15:33:19 | M7: tools/ui_e2e/screenshots/full/AH_PROT_AdminDocUtilDocAgents.png
A8: AH-SP-050-docutil-doc-agents | B8: DocUtil 에이전트 | C8: BFF 데이터 로드 (DocUtil → AgentHub BFF) | D8: (admin 로그인) | E8: /admin/docutil-doc-agents 진입 | F8: DocUtil API 응답 또는 5xx 시 한국어 에러 토스트 | G8: safe | H8: auto | I8: PASS | K8: [라이브 라우트 결과 인용] AdminDocUtilDocAgents: PASS | L8: 2026-05-12 (인용)

Sheet AdminDocUtilDocumentsV2
A1: ID | B1: 화면 | C1: 인터랙션 | D1: 사전조건 | E1: 입력/액션 | F1: 기대 결과 | G1: 위험도 | H1: 자동화 | I1: 결과 | J1: 실측값 | K1: 비고 | L1: 검증일시 | M1: 스크린샷 경로
A2: AH-040-01 | B2: AdminDocUtilDocumentsV2 | C2: 화면 진입 (admin 세션) | D2: (admin 로그인) — public 라우트도 admin 세션 보유 상태에서 진입 | E2: GET /admin/docutil-documents-v2 | F2: HTTP 200 또는 클라이언트 라우팅 성공 + 페이지 마운트 (Vue/Next 컴포넌트 렌더) | G2: safe | H2: auto | I2: PASS | J2: DOM mounted=True | duration=1799ms | final=http://192.168.10.39:64005/admin/docutil-documents-v2 | L2: 2026-05-12 15:33:21 | M2: tools/ui_e2e/screenshots/full/AH_PROT_AdminDocUtilDocumentsV2.png
A3: AH-040-02 | B3: AdminDocUtilDocumentsV2 | C3: 권한 분기 (anonymous → /login 리다이렉트) | D3: (미로그인 + 새 컨텍스트) | E3: GET /admin/docutil-documents-v2 (token 없음) | F3: /login?redirect=... 또는 /landing 으로 리다이렉트 | G3: safe | H3: auto | I3: PASS | J3: final=http://192.168.10.39:64005/login?redirect=/admin/docutil-documents-v2 | K3: final=http://192.168.10.39:64005/login?redirect=/admin/docutil-documents-v2 | L3: 2026-05-12 15:40:00
A4: AH-040-03 | B4: AdminDocUtilDocumentsV2 | C4: DOM 마운트 + 주요 컨테이너 렌더 | D4: (라우트 진입 완료) | E4: DOM 로드 + 1초 대기 → console error 0건 + 핵심 selector 가시 | F4: console error 0건 (잘 알려진 외부 라이브러리 경고 제외), 핵심 컨테이너(main/main-layout/page-root) 렌더 | G4: safe | H4: auto | I4: PASS | L4: 2026-05-12 15:33:21
A5: AH-040-04 | B5: AdminDocUtilDocumentsV2 | C5: 페이지 진입 시 API 자동 호출 응답 확인 | D5: (라우트 진입 완료) | E5: network 모니터 — 첫 5초 내 발생한 /api 또는 /v1 호출 + 상태코드 수집 | F5: 관련 API 200 OK 또는 비-401 응답. 401 발생 시 권한 분기 케이스로 분류 | G5: safe | H5: auto | I5: PASS | L5: 2026-05-12 15:33:21
A6: AH-040-05 | B6: AdminDocUtilDocumentsV2 | C6: 사이드바 / 헤더 / 활성 메뉴 표시 | D6: (라우트 진입 완료) | E6: 선택된 메뉴 highlight + 현재 사용자(admin) 정보 표시 확인 | F6: 사이드바 노드 활성 클래스 + 사용자 아바타/이름 가시 | G6: safe | H6: auto | I6: PASS | L6: 2026-05-12 15:33:21
A7: AH-040-06 | B7: AdminDocUtilDocumentsV2 | C7: 스크린샷 캡처 (감사용) | D7: (라우트 진입 + DOM 안정화) | E7: viewport 스크린샷 (full=false) | F7: screenshots/full/ 하위 .png 저장됨 (평문 시크릿 없음) | G7: safe | H7: auto | I7: PASS | L7: 2026-05-12 15:33:21 | M7: tools/ui_e2e/screenshots/full/AH_PROT_AdminDocUtilDocumentsV2.png
A8: AH-SP-050-docutil-documents-v2 | B8: DocUtil 문서 V2 | C8: BFF 데이터 로드 (DocUtil → AgentHub BFF) | D8: (admin 로그인) | E8: /admin/docutil-documents-v2 진입 | F8: DocUtil API 응답 또는 5xx 시 한국어 에러 토스트 | G8: safe | H8: auto | I8: PASS | K8: [라이브 라우트 결과 인용] AdminDocUtilDocumentsV2: PASS | L8: 2026-05-12 (인용)

Sheet AdminDocUtilEvaluation
A1: ID | B1: 화면 | C1: 인터랙션 | D1: 사전조건 | E1: 입력/액션 | F1: 기대 결과 | G1: 위험도 | H1: 자동화 | I1: 결과 | J1: 실측값 | K1: 비고 | L1: 검증일시 | M1: 스크린샷 경로
A2: AH-034-01 | B2: AdminDocUtilEvaluation | C2: 화면 진입 (admin 세션) | D2: (admin 로그인) — public 라우트도 admin 세션 보유 상태에서 진입 | E2: GET /admin/docutil-evaluation | F2: HTTP 200 또는 클라이언트 라우팅 성공 + 페이지 마운트 (Vue/Next 컴포넌트 렌더) | G2: safe | H2: auto | I2: PASS | J2: DOM mounted=True | duration=1795ms | final=http://192.168.10.39:64005/admin/docutil-evaluation | L2: 2026-05-12 15:33:10 | M2: tools/ui_e2e/screenshots/full/AH_PROT_AdminDocUtilEvaluation.png
A3: AH-034-02 | B3: AdminDocUtilEvaluation | C3: 권한 분기 (anonymous → /login 리다이렉트) | D3: (미로그인 + 새 컨텍스트) | E3: GET /admin/docutil-evaluation (token 없음) | F3: /login?redirect=... 또는 /landing 으로 리다이렉트 | G3: safe | H3: auto | I3: PASS | J3: final=http://192.168.10.39:64005/login?redirect=/admin/docutil-evaluation | K3: final=http://192.168.10.39:64005/login?redirect=/admin/docutil-evaluation | L3: 2026-05-12 15:40:00
A4: AH-034-03 | B4: AdminDocUtilEvaluation | C4: DOM 마운트 + 주요 컨테이너 렌더 | D4: (라우트 진입 완료) | E4: DOM 로드 + 1초 대기 → console error 0건 + 핵심 selector 가시 | F4: console error 0건 (잘 알려진 외부 라이브러리 경고 제외), 핵심 컨테이너(main/main-layout/page-root) 렌더 | G4: safe | H4: auto | I4: PASS | L4: 2026-05-12 15:33:10
A5: AH-034-04 | B5: AdminDocUtilEvaluation | C5: 페이지 진입 시 API 자동 호출 응답 확인 | D5: (라우트 진입 완료) | E5: network 모니터 — 첫 5초 내 발생한 /api 또는 /v1 호출 + 상태코드 수집 | F5: 관련 API 200 OK 또는 비-401 응답. 401 발생 시 권한 분기 케이스로 분류 | G5: safe | H5: auto | I5: PASS | L5: 2026-05-12 15:33:10
A6: AH-034-05 | B6: AdminDocUtilEvaluation | C6: 사이드바 / 헤더 / 활성 메뉴 표시 | D6: (라우트 진입 완료) | E6: 선택된 메뉴 highlight + 현재 사용자(admin) 정보 표시 확인 | F6: 사이드바 노드 활성 클래스 + 사용자 아바타/이름 가시 | G6: safe | H6: auto | I6: PASS | L6: 2026-05-12 15:33:10
A7: AH-034-06 | B7: AdminDocUtilEvaluation | C7: 스크린샷 캡처 (감사용) | D7: (라우트 진입 + DOM 안정화) | E7: viewport 스크린샷 (full=false) | F7: screenshots/full/ 하위 .png 저장됨 (평문 시크릿 없음) | G7: safe | H7: auto | I7: PASS | L7: 2026-05-12 15:33:10 | M7: tools/ui_e2e/screenshots/full/AH_PROT_AdminDocUtilEvaluation.png
A8: AH-SP-050-docutil-evaluation | B8: DocUtil 평가 | C8: BFF 데이터 로드 (DocUtil → AgentHub BFF) | D8: (admin 로그인) | E8: /admin/docutil-evaluation 진입 | F8: DocUtil API 응답 또는 5xx 시 한국어 에러 토스트 | G8: safe | H8: auto | I8: PASS | K8: [라이브 라우트 결과 인용] AdminDocUtilEvaluation: PASS | L8: 2026-05-12 (인용)

Sheet AdminDocUtilFaq
A1: ID | B1: 화면 | C1: 인터랙션 | D1: 사전조건 | E1: 입력/액션 | F1: 기대 결과 | G1: 위험도 | H1: 자동화 | I1: 결과 | J1: 실측값 | K1: 비고 | L1: 검증일시 | M1: 스크린샷 경로
A2: AH-035-01 | B2: AdminDocUtilFaq | C2: 화면 진입 (admin 세션) | D2: (admin 로그인) — public 라우트도 admin 세션 보유 상태에서 진입 | E2: GET /admin/docutil-faq | F2: HTTP 200 또는 클라이언트 라우팅 성공 + 페이지 마운트 (Vue/Next 컴포넌트 렌더) | G2: safe | H2: auto | I2: PASS | J2: DOM mounted=True | duration=1780ms | final=http://192.168.10.39:64005/admin/docutil-faq | L2: 2026-05-12 15:33:12 | M2: tools/ui_e2e/screenshots/full/AH_PROT_AdminDocUtilFaq.png
A3: AH-035-02 | B3: AdminDocUtilFaq | C3: 권한 분기 (anonymous → /login 리다이렉트) | D3: (미로그인 + 새 컨텍스트) | E3: GET /admin/docutil-faq (token 없음) | F3: /login?redirect=... 또는 /landing 으로 리다이렉트 | G3: safe | H3: auto | I3: PASS | J3: final=http://192.168.10.39:64005/login?redirect=/admin/docutil-faq | K3: final=http://192.168.10.39:64005/login?redirect=/admin/docutil-faq | L3: 2026-05-12 15:40:00
A4: AH-035-03 | B4: AdminDocUtilFaq | C4: DOM 마운트 + 주요 컨테이너 렌더 | D4: (라우트 진입 완료) | E4: DOM 로드 + 1초 대기 → console error 0건 + 핵심 selector 가시 | F4: console error 0건 (잘 알려진 외부 라이브러리 경고 제외), 핵심 컨테이너(main/main-layout/page-root) 렌더 | G4: safe | H4: auto | I4: PASS | L4: 2026-05-12 15:33:12
A5: AH-035-04 | B5: AdminDocUtilFaq | C5: 페이지 진입 시 API 자동 호출 응답 확인 | D5: (라우트 진입 완료) | E5: network 모니터 — 첫 5초 내 발생한 /api 또는 /v1 호출 + 상태코드 수집 | F5: 관련 API 200 OK 또는 비-401 응답. 401 발생 시 권한 분기 케이스로 분류 | G5: safe | H5: auto | I5: PASS | L5: 2026-05-12 15:33:12
A6: AH-035-05 | B6: AdminDocUtilFaq | C6: 사이드바 / 헤더 / 활성 메뉴 표시 | D6: (라우트 진입 완료) | E6: 선택된 메뉴 highlight + 현재 사용자(admin) 정보 표시 확인 | F6: 사이드바 노드 활성 클래스 + 사용자 아바타/이름 가시 | G6: safe | H6: auto | I6: PASS | L6: 2026-05-12 15:33:12
A7: AH-035-06 | B7: AdminDocUtilFaq | C7: 스크린샷 캡처 (감사용) | D7: (라우트 진입 + DOM 안정화) | E7: viewport 스크린샷 (full=false) | F7: screenshots/full/ 하위 .png 저장됨 (평문 시크릿 없음) | G7: safe | H7: auto | I7: PASS | L7: 2026-05-12 15:33:12 | M7: tools/ui_e2e/screenshots/full/AH_PROT_AdminDocUtilFaq.png
A8: AH-SP-050-docutil-faq | B8: DocUtil FAQ | C8: BFF 데이터 로드 (DocUtil → AgentHub BFF) | D8: (admin 로그인) | E8: /admin/docutil-faq 진입 | F8: DocUtil API 응답 또는 5xx 시 한국어 에러 토스트 | G8: safe | H8: auto | I8: PASS | K8: [라이브 라우트 결과 인용] AdminDocUtilFaq: PASS | L8: 2026-05-12 (인용)

Sheet AdminDocUtilProjects
A1: ID | B1: 화면 | C1: 인터랙션 | D1: 사전조건 | E1: 입력/액션 | F1: 기대 결과 | G1: 위험도 | H1: 자동화 | I1: 결과 | J1: 실측값 | K1: 비고 | L1: 검증일시 | M1: 스크린샷 경로
A2: AH-030-01 | B2: AdminDocUtilProjects | C2: 화면 진입 (admin 세션) | D2: (admin 로그인) — public 라우트도 admin 세션 보유 상태에서 진입 | E2: GET /admin/docutil-projects | F2: HTTP 200 또는 클라이언트 라우팅 성공 + 페이지 마운트 (Vue/Next 컴포넌트 렌더) | G2: safe | H2: auto | I2: PASS | J2: DOM mounted=True | duration=1779ms | final=http://192.168.10.39:64005/admin/docutil-projects | L2: 2026-05-12 15:33:03 | M2: tools/ui_e2e/screenshots/full/AH_PROT_AdminDocUtilProjects.png
A3: AH-030-02 | B3: AdminDocUtilProjects | C3: 권한 분기 (anonymous → /login 리다이렉트) | D3: (미로그인 + 새 컨텍스트) | E3: GET /admin/docutil-projects (token 없음) | F3: /login?redirect=... 또는 /landing 으로 리다이렉트 | G3: safe | H3: auto | I3: PASS | J3: final=http://192.168.10.39:64005/login?redirect=/admin/docutil-projects | K3: final=http://192.168.10.39:64005/login?redirect=/admin/docutil-projects | L3: 2026-05-12 15:40:00
A4: AH-030-03 | B4: AdminDocUtilProjects | C4: DOM 마운트 + 주요 컨테이너 렌더 | D4: (라우트 진입 완료) | E4: DOM 로드 + 1초 대기 → console error 0건 + 핵심 selector 가시 | F4: console error 0건 (잘 알려진 외부 라이브러리 경고 제외), 핵심 컨테이너(main/main-layout/page-root) 렌더 | G4: safe | H4: auto | I4: PASS | L4: 2026-05-12 15:33:03
A5: AH-030-04 | B5: AdminDocUtilProjects | C5: 페이지 진입 시 API 자동 호출 응답 확인 | D5: (라우트 진입 완료) | E5: network 모니터 — 첫 5초 내 발생한 /api 또는 /v1 호출 + 상태코드 수집 | F5: 관련 API 200 OK 또는 비-401 응답. 401 발생 시 권한 분기 케이스로 분류 | G5: safe | H5: auto | I5: PASS | L5: 2026-05-12 15:33:03
A6: AH-030-05 | B6: AdminDocUtilProjects | C6: 사이드바 / 헤더 / 활성 메뉴 표시 | D6: (라우트 진입 완료) | E6: 선택된 메뉴 highlight + 현재 사용자(admin) 정보 표시 확인 | F6: 사이드바 노드 활성 클래스 + 사용자 아바타/이름 가시 | G6: safe | H6: auto | I6: PASS | L6: 2026-05-12 15:33:03
A7: AH-030-06 | B7: AdminDocUtilProjects | C7: 스크린샷 캡처 (감사용) | D7: (라우트 진입 + DOM 안정화) | E7: viewport 스크린샷 (full=false) | F7: screenshots/full/ 하위 .png 저장됨 (평문 시크릿 없음) | G7: safe | H7: auto | I7: PASS | L7: 2026-05-12 15:33:03 | M7: tools/ui_e2e/screenshots/full/AH_PROT_AdminDocUtilProjects.png
A8: AH-SP-050-docutil-projects | B8: DocUtil 프로젝트 | C8: BFF 데이터 로드 (DocUtil → AgentHub BFF) | D8: (admin 로그인) | E8: /admin/docutil-projects 진입 | F8: DocUtil API 응답 또는 5xx 시 한국어 에러 토스트 | G8: safe | H8: auto | I8: PASS | K8: [라이브 라우트 결과 인용] AdminDocUtilProjects: PASS | L8: 2026-05-12 (인용)

Sheet AdminDocUtilReports
A1: ID | B1: 화면 | C1: 인터랙션 | D1: 사전조건 | E1: 입력/액션 | F1: 기대 결과 | G1: 위험도 | H1: 자동화 | I1: 결과 | J1: 실측값 | K1: 비고 | L1: 검증일시 | M1: 스크린샷 경로
A2: AH-036-01 | B2: AdminDocUtilReports | C2: 화면 진입 (admin 세션) | D2: (admin 로그인) — public 라우트도 admin 세션 보유 상태에서 진입 | E2: GET /admin/docutil-reports | F2: HTTP 200 또는 클라이언트 라우팅 성공 + 페이지 마운트 (Vue/Next 컴포넌트 렌더) | G2: safe | H2: auto | I2: PASS | J2: DOM mounted=True | duration=1799ms | final=http://192.168.10.39:64005/admin/docutil-reports | L2: 2026-05-12 15:33:13 | M2: tools/ui_e2e/screenshots/full/AH_PROT_AdminDocUtilReports.png
A3: AH-036-02 | B3: AdminDocUtilReports | C3: 권한 분기 (anonymous → /login 리다이렉트) | D3: (미로그인 + 새 컨텍스트) | E3: GET /admin/docutil-reports (token 없음) | F3: /login?redirect=... 또는 /landing 으로 리다이렉트 | G3: safe | H3: auto | I3: PASS | J3: final=http://192.168.10.39:64005/login?redirect=/admin/docutil-reports | K3: final=http://192.168.10.39:64005/login?redirect=/admin/docutil-reports | L3: 2026-05-12 15:40:00
A4: AH-036-03 | B4: AdminDocUtilReports | C4: DOM 마운트 + 주요 컨테이너 렌더 | D4: (라우트 진입 완료) | E4: DOM 로드 + 1초 대기 → console error 0건 + 핵심 selector 가시 | F4: console error 0건 (잘 알려진 외부 라이브러리 경고 제외), 핵심 컨테이너(main/main-layout/page-root) 렌더 | G4: safe | H4: auto | I4: PASS | L4: 2026-05-12 15:33:13
A5: AH-036-04 | B5: AdminDocUtilReports | C5: 페이지 진입 시 API 자동 호출 응답 확인 | D5: (라우트 진입 완료) | E5: network 모니터 — 첫 5초 내 발생한 /api 또는 /v1 호출 + 상태코드 수집 | F5: 관련 API 200 OK 또는 비-401 응답. 401 발생 시 권한 분기 케이스로 분류 | G5: safe | H5: auto | I5: PASS | L5: 2026-05-12 15:33:13
A6: AH-036-05 | B6: AdminDocUtilReports | C6: 사이드바 / 헤더 / 활성 메뉴 표시 | D6: (라우트 진입 완료) | E6: 선택된 메뉴 highlight + 현재 사용자(admin) 정보 표시 확인 | F6: 사이드바 노드 활성 클래스 + 사용자 아바타/이름 가시 | G6: safe | H6: auto | I6: PASS | L6: 2026-05-12 15:33:13
A7: AH-036-06 | B7: AdminDocUtilReports | C7: 스크린샷 캡처 (감사용) | D7: (라우트 진입 + DOM 안정화) | E7: viewport 스크린샷 (full=false) | F7: screenshots/full/ 하위 .png 저장됨 (평문 시크릿 없음) | G7: safe | H7: auto | I7: PASS | L7: 2026-05-12 15:33:13 | M7: tools/ui_e2e/screenshots/full/AH_PROT_AdminDocUtilReports.png
A8: AH-SP-050-docutil-reports | B8: DocUtil 보고서 | C8: BFF 데이터 로드 (DocUtil → AgentHub BFF) | D8: (admin 로그인) | E8: /admin/docutil-reports 진입 | F8: DocUtil API 응답 또는 5xx 시 한국어 에러 토스트 | G8: safe | H8: auto | I8: PASS | K8: [라이브 라우트 결과 인용] AdminDocUtilReports: PASS | L8: 2026-05-12 (인용)

Sheet AdminDocUtilSearchScopes
A1: ID | B1: 화면 | C1: 인터랙션 | D1: 사전조건 | E1: 입력/액션 | F1: 기대 결과 | G1: 위험도 | H1: 자동화 | I1: 결과 | J1: 실측값 | K1: 비고 | L1: 검증일시 | M1: 스크린샷 경로
A2: AH-033-01 | B2: AdminDocUtilSearchScopes | C2: 화면 진입 (admin 세션) | D2: (admin 로그인) — public 라우트도 admin 세션 보유 상태에서 진입 | E2: GET /admin/docutil-search-scopes | F2: HTTP 200 또는 클라이언트 라우팅 성공 + 페이지 마운트 (Vue/Next 컴포넌트 렌더) | G2: safe | H2: auto | I2: PASS | J2: DOM mounted=True | duration=1782ms | final=http://192.168.10.39:64005/admin/docutil-search-scopes | L2: 2026-05-12 15:33:08 | M2: tools/ui_e2e/screenshots/full/AH_PROT_AdminDocUtilSearchScopes.png
A3: AH-033-02 | B3: AdminDocUtilSearchScopes | C3: 권한 분기 (anonymous → /login 리다이렉트) | D3: (미로그인 + 새 컨텍스트) | E3: GET /admin/docutil-search-scopes (token 없음) | F3: /login?redirect=... 또는 /landing 으로 리다이렉트 | G3: safe | H3: auto | I3: PASS | J3: final=http://192.168.10.39:64005/login?redirect=/admin/docutil-search-scopes | K3: final=http://192.168.10.39:64005/login?redirect=/admin/docutil-search-scopes | L3: 2026-05-12 15:40:00
A4: AH-033-03 | B4: AdminDocUtilSearchScopes | C4: DOM 마운트 + 주요 컨테이너 렌더 | D4: (라우트 진입 완료) | E4: DOM 로드 + 1초 대기 → console error 0건 + 핵심 selector 가시 | F4: console error 0건 (잘 알려진 외부 라이브러리 경고 제외), 핵심 컨테이너(main/main-layout/page-root) 렌더 | G4: safe | H4: auto | I4: PASS | L4: 2026-05-12 15:33:08
A5: AH-033-04 | B5: AdminDocUtilSearchScopes | C5: 페이지 진입 시 API 자동 호출 응답 확인 | D5: (라우트 진입 완료) | E5: network 모니터 — 첫 5초 내 발생한 /api 또는 /v1 호출 + 상태코드 수집 | F5: 관련 API 200 OK 또는 비-401 응답. 401 발생 시 권한 분기 케이스로 분류 | G5: safe | H5: auto | I5: PASS | L5: 2026-05-12 15:33:08
A6: AH-033-05 | B6: AdminDocUtilSearchScopes | C6: 사이드바 / 헤더 / 활성 메뉴 표시 | D6: (라우트 진입 완료) | E6: 선택된 메뉴 highlight + 현재 사용자(admin) 정보 표시 확인 | F6: 사이드바 노드 활성 클래스 + 사용자 아바타/이름 가시 | G6: safe | H6: auto | I6: PASS | L6: 2026-05-12 15:33:08
A7: AH-033-06 | B7: AdminDocUtilSearchScopes | C7: 스크린샷 캡처 (감사용) | D7: (라우트 진입 + DOM 안정화) | E7: viewport 스크린샷 (full=false) | F7: screenshots/full/ 하위 .png 저장됨 (평문 시크릿 없음) | G7: safe | H7: auto | I7: PASS | L7: 2026-05-12 15:33:08 | M7: tools/ui_e2e/screenshots/full/AH_PROT_AdminDocUtilSearchScopes.png
A8: AH-SP-050-docutil-search-scopes | B8: DocUtil 검색범위 | C8: BFF 데이터 로드 (DocUtil → AgentHub BFF) | D8: (admin 로그인) | E8: /admin/docutil-search-scopes 진입 | F8: DocUtil API 응답 또는 5xx 시 한국어 에러 토스트 | G8: safe | H8: auto | I8: PASS | K8: [라이브 라우트 결과 인용] AdminDocUtilSearchScopes: PASS | L8: 2026-05-12 (인용)

Sheet AdminDocUtilTemplates
A1: ID | B1: 화면 | C1: 인터랙션 | D1: 사전조건 | E1: 입력/액션 | F1: 기대 결과 | G1: 위험도 | H1: 자동화 | I1: 결과 | J1: 실측값 | K1: 비고 | L1: 검증일시 | M1: 스크린샷 경로
A2: AH-037-01 | B2: AdminDocUtilTemplates | C2: 화면 진입 (admin 세션) | D2: (admin 로그인) — public 라우트도 admin 세션 보유 상태에서 진입 | E2: GET /admin/docutil-templates | F2: HTTP 200 또는 클라이언트 라우팅 성공 + 페이지 마운트 (Vue/Next 컴포넌트 렌더) | G2: safe | H2: auto | I2: PASS | J2: DOM mounted=True | duration=1800ms | final=http://192.168.10.39:64005/admin/docutil-templates | L2: 2026-05-12 15:33:15 | M2: tools/ui_e2e/screenshots/full/AH_PROT_AdminDocUtilTemplates.png
A3: AH-037-02 | B3: AdminDocUtilTemplates | C3: 권한 분기 (anonymous → /login 리다이렉트) | D3: (미로그인 + 새 컨텍스트) | E3: GET /admin/docutil-templates (token 없음) | F3: /login?redirect=... 또는 /landing 으로 리다이렉트 | G3: safe | H3: auto | I3: PASS | J3: final=http://192.168.10.39:64005/login?redirect=/admin/docutil-templates | K3: final=http://192.168.10.39:64005/login?redirect=/admin/docutil-templates | L3: 2026-05-12 15:40:00
A4: AH-037-03 | B4: AdminDocUtilTemplates | C4: DOM 마운트 + 주요 컨테이너 렌더 | D4: (라우트 진입 완료) | E4: DOM 로드 + 1초 대기 → console error 0건 + 핵심 selector 가시 | F4: console error 0건 (잘 알려진 외부 라이브러리 경고 제외), 핵심 컨테이너(main/main-layout/page-root) 렌더 | G4: safe | H4: auto | I4: PASS | L4: 2026-05-12 15:33:15
A5: AH-037-04 | B5: AdminDocUtilTemplates | C5: 페이지 진입 시 API 자동 호출 응답 확인 | D5: (라우트 진입 완료) | E5: network 모니터 — 첫 5초 내 발생한 /api 또는 /v1 호출 + 상태코드 수집 | F5: 관련 API 200 OK 또는 비-401 응답. 401 발생 시 권한 분기 케이스로 분류 | G5: safe | H5: auto | I5: PASS | L5: 2026-05-12 15:33:15
A6: AH-037-05 | B6: AdminDocUtilTemplates | C6: 사이드바 / 헤더 / 활성 메뉴 표시 | D6: (라우트 진입 완료) | E6: 선택된 메뉴 highlight + 현재 사용자(admin) 정보 표시 확인 | F6: 사이드바 노드 활성 클래스 + 사용자 아바타/이름 가시 | G6: safe | H6: auto | I6: PASS | L6: 2026-05-12 15:33:15
A7: AH-037-06 | B7: AdminDocUtilTemplates | C7: 스크린샷 캡처 (감사용) | D7: (라우트 진입 + DOM 안정화) | E7: viewport 스크린샷 (full=false) | F7: screenshots/full/ 하위 .png 저장됨 (평문 시크릿 없음) | G7: safe | H7: auto | I7: PASS | L7: 2026-05-12 15:33:15 | M7: tools/ui_e2e/screenshots/full/AH_PROT_AdminDocUtilTemplates.png
A8: AH-SP-050-docutil-templates | B8: DocUtil 템플릿 | C8: BFF 데이터 로드 (DocUtil → AgentHub BFF) | D8: (admin 로그인) | E8: /admin/docutil-templates 진입 | F8: DocUtil API 응답 또는 5xx 시 한국어 에러 토스트 | G8: safe | H8: auto | I8: PASS | K8: [라이브 라우트 결과 인용] AdminDocUtilTemplates: PASS | L8: 2026-05-12 (인용)

Sheet AdminDocUtilUsers
A1: ID | B1: 화면 | C1: 인터랙션 | D1: 사전조건 | E1: 입력/액션 | F1: 기대 결과 | G1: 위험도 | H1: 자동화 | I1: 결과 | J1: 실측값 | K1: 비고 | L1: 검증일시 | M1: 스크린샷 경로
A2: AH-028-01 | B2: AdminDocUtilUsers | C2: 화면 진입 (admin 세션) | D2: (admin 로그인) — public 라우트도 admin 세션 보유 상태에서 진입 | E2: GET /admin/docutil-users | F2: HTTP 200 또는 클라이언트 라우팅 성공 + 페이지 마운트 (Vue/Next 컴포넌트 렌더) | G2: safe | H2: auto | I2: PASS | J2: DOM mounted=True | duration=1802ms | final=http://192.168.10.39:64005/admin/docutil-users | L2: 2026-05-12 15:32:59 | M2: tools/ui_e2e/screenshots/full/AH_PROT_AdminDocUtilUsers.png
A3: AH-028-02 | B3: AdminDocUtilUsers | C3: 권한 분기 (anonymous → /login 리다이렉트) | D3: (미로그인 + 새 컨텍스트) | E3: GET /admin/docutil-users (token 없음) | F3: /login?redirect=... 또는 /landing 으로 리다이렉트 | G3: safe | H3: auto | I3: PASS | J3: final=http://192.168.10.39:64005/login?redirect=/admin/docutil-users | K3: final=http://192.168.10.39:64005/login?redirect=/admin/docutil-users | L3: 2026-05-12 15:40:00
A4: AH-028-03 | B4: AdminDocUtilUsers | C4: DOM 마운트 + 주요 컨테이너 렌더 | D4: (라우트 진입 완료) | E4: DOM 로드 + 1초 대기 → console error 0건 + 핵심 selector 가시 | F4: console error 0건 (잘 알려진 외부 라이브러리 경고 제외), 핵심 컨테이너(main/main-layout/page-root) 렌더 | G4: safe | H4: auto | I4: PASS | L4: 2026-05-12 15:32:59
A5: AH-028-04 | B5: AdminDocUtilUsers | C5: 페이지 진입 시 API 자동 호출 응답 확인 | D5: (라우트 진입 완료) | E5: network 모니터 — 첫 5초 내 발생한 /api 또는 /v1 호출 + 상태코드 수집 | F5: 관련 API 200 OK 또는 비-401 응답. 401 발생 시 권한 분기 케이스로 분류 | G5: safe | H5: auto | I5: PASS | L5: 2026-05-12 15:32:59
A6: AH-028-05 | B6: AdminDocUtilUsers | C6: 사이드바 / 헤더 / 활성 메뉴 표시 | D6: (라우트 진입 완료) | E6: 선택된 메뉴 highlight + 현재 사용자(admin) 정보 표시 확인 | F6: 사이드바 노드 활성 클래스 + 사용자 아바타/이름 가시 | G6: safe | H6: auto | I6: PASS | L6: 2026-05-12 15:32:59
A7: AH-028-06 | B7: AdminDocUtilUsers | C7: 스크린샷 캡처 (감사용) | D7: (라우트 진입 + DOM 안정화) | E7: viewport 스크린샷 (full=false) | F7: screenshots/full/ 하위 .png 저장됨 (평문 시크릿 없음) | G7: safe | H7: auto | I7: PASS | L7: 2026-05-12 15:32:59 | M7: tools/ui_e2e/screenshots/full/AH_PROT_AdminDocUtilUsers.png
A8: AH-SP-050-docutil-users | B8: DocUtil 사용자 | C8: BFF 데이터 로드 (DocUtil → AgentHub BFF) | D8: (admin 로그인) | E8: /admin/docutil-users 진입 | F8: DocUtil API 응답 또는 5xx 시 한국어 에러 토스트 | G8: safe | H8: auto | I8: PASS | K8: [라이브 라우트 결과 인용] AdminDocUtilUsers: PASS | L8: 2026-05-12 (인용)

Sheet AdminKnowledgeBase
A1: ID | B1: 화면 | C1: 인터랙션 | D1: 사전조건 | E1: 입력/액션 | F1: 기대 결과 | G1: 위험도 | H1: 자동화 | I1: 결과 | J1: 실측값 | K1: 비고 | L1: 검증일시 | M1: 스크린샷 경로
A2: AH-025-01 | B2: AdminKnowledgeBase | C2: 화면 진입 (admin 세션) | D2: (admin 로그인) — public 라우트도 admin 세션 보유 상태에서 진입 | E2: GET /admin/knowledge-base | F2: HTTP 200 또는 클라이언트 라우팅 성공 + 페이지 마운트 (Vue/Next 컴포넌트 렌더) | G2: safe | H2: auto | I2: PASS | J2: DOM mounted=True | duration=1822ms | final=http://192.168.10.39:64005/admin/knowledge-base | L2: 2026-05-12 15:32:54 | M2: tools/ui_e2e/screenshots/full/AH_PROT_AdminKnowledgeBase.png
A3: AH-025-02 | B3: AdminKnowledgeBase | C3: 권한 분기 (anonymous → /login 리다이렉트) | D3: (미로그인 + 새 컨텍스트) | E3: GET /admin/knowledge-base (token 없음) | F3: /login?redirect=... 또는 /landing 으로 리다이렉트 | G3: safe | H3: auto | I3: PASS | J3: final=http://192.168.10.39:64005/login?redirect=/admin/knowledge-base (redirected to http://192.168.10.39:64005/login?redirect=/admin/knowledge-base) | L3: 2026-05-12 15:34:01
A4: AH-025-03 | B4: AdminKnowledgeBase | C4: DOM 마운트 + 주요 컨테이너 렌더 | D4: (라우트 진입 완료) | E4: DOM 로드 + 1초 대기 → console error 0건 + 핵심 selector 가시 | F4: console error 0건 (잘 알려진 외부 라이브러리 경고 제외), 핵심 컨테이너(main/main-layout/page-root) 렌더 | G4: safe | H4: auto | I4: PASS | L4: 2026-05-12 15:32:54
A5: AH-025-04 | B5: AdminKnowledgeBase | C5: 페이지 진입 시 API 자동 호출 응답 확인 | D5: (라우트 진입 완료) | E5: network 모니터 — 첫 5초 내 발생한 /api 또는 /v1 호출 + 상태코드 수집 | F5: 관련 API 200 OK 또는 비-401 응답. 401 발생 시 권한 분기 케이스로 분류 | G5: safe | H5: auto | I5: PASS | L5: 2026-05-12 15:32:54
A6: AH-025-05 | B6: AdminKnowledgeBase | C6: 사이드바 / 헤더 / 활성 메뉴 표시 | D6: (라우트 진입 완료) | E6: 선택된 메뉴 highlight + 현재 사용자(admin) 정보 표시 확인 | F6: 사이드바 노드 활성 클래스 + 사용자 아바타/이름 가시 | G6: safe | H6: auto | I6: PASS | L6: 2026-05-12 15:32:54
A7: AH-025-06 | B7: AdminKnowledgeBase | C7: 스크린샷 캡처 (감사용) | D7: (라우트 진입 + DOM 안정화) | E7: viewport 스크린샷 (full=false) | F7: screenshots/full/ 하위 .png 저장됨 (평문 시크릿 없음) | G7: safe | H7: auto | I7: PASS | L7: 2026-05-12 15:32:54 | M7: tools/ui_e2e/screenshots/full/AH_PROT_AdminKnowledgeBase.png
A8: AH-SP-040 | B8: 운영자 KB | C8: KB 컬렉션 목록 로드 (DocUtil BFF) | D8: (admin 로그인) | E8: /admin/knowledge-base 진입 | F8: DocUtil collections 목록 표시 또는 빈 상태 UI | G8: safe | H8: auto | I8: PASS | K8: [라이브 라우트 결과 인용] AdminKnowledgeBase: PASS | L8: 2026-05-12 (인용)

Sheet AdminKnowledgeBaseUpload
A1: ID | B1: 화면 | C1: 인터랙션 | D1: 사전조건 | E1: 입력/액션 | F1: 기대 결과 | G1: 위험도 | H1: 자동화 | I1: 결과 | J1: 실측값 | K1: 비고 | L1: 검증일시 | M1: 스크린샷 경로
A2: AH-026-01 | B2: AdminKnowledgeBaseUpload | C2: 화면 진입 (admin 세션) | D2: (admin 로그인) — public 라우트도 admin 세션 보유 상태에서 진입 | E2: GET /admin/knowledge-base/upload | F2: HTTP 200 또는 클라이언트 라우팅 성공 + 페이지 마운트 (Vue/Next 컴포넌트 렌더) | G2: safe | H2: auto | I2: PASS | J2: DOM mounted=True | duration=1791ms | final=http://192.168.10.39:64005/admin/knowledge-base/upload | L2: 2026-05-12 15:32:56 | M2: tools/ui_e2e/screenshots/full/AH_PROT_AdminKnowledgeBaseUpload.png
A3: AH-026-02 | B3: AdminKnowledgeBaseUpload | C3: 권한 분기 (anonymous → /login 리다이렉트) | D3: (미로그인 + 새 컨텍스트) | E3: GET /admin/knowledge-base/upload (token 없음) | F3: /login?redirect=... 또는 /landing 으로 리다이렉트 | G3: safe | H3: auto | I3: PASS | J3: final=http://192.168.10.39:64005/login?redirect=/admin/knowledge-base/upload | K3: final=http://192.168.10.39:64005/login?redirect=/admin/knowledge-base/upload | L3: 2026-05-12 15:40:00
A4: AH-026-03 | B4: AdminKnowledgeBaseUpload | C4: DOM 마운트 + 주요 컨테이너 렌더 | D4: (라우트 진입 완료) | E4: DOM 로드 + 1초 대기 → console error 0건 + 핵심 selector 가시 | F4: console error 0건 (잘 알려진 외부 라이브러리 경고 제외), 핵심 컨테이너(main/main-layout/page-root) 렌더 | G4: safe | H4: auto | I4: PASS | L4: 2026-05-12 15:32:56
A5: AH-026-04 | B5: AdminKnowledgeBaseUpload | C5: 페이지 진입 시 API 자동 호출 응답 확인 | D5: (라우트 진입 완료) | E5: network 모니터 — 첫 5초 내 발생한 /api 또는 /v1 호출 + 상태코드 수집 | F5: 관련 API 200 OK 또는 비-401 응답. 401 발생 시 권한 분기 케이스로 분류 | G5: safe | H5: auto | I5: PASS | L5: 2026-05-12 15:32:56
A6: AH-026-05 | B6: AdminKnowledgeBaseUpload | C6: 사이드바 / 헤더 / 활성 메뉴 표시 | D6: (라우트 진입 완료) | E6: 선택된 메뉴 highlight + 현재 사용자(admin) 정보 표시 확인 | F6: 사이드바 노드 활성 클래스 + 사용자 아바타/이름 가시 | G6: safe | H6: auto | I6: PASS | L6: 2026-05-12 15:32:56
A7: AH-026-06 | B7: AdminKnowledgeBaseUpload | C7: 스크린샷 캡처 (감사용) | D7: (라우트 진입 + DOM 안정화) | E7: viewport 스크린샷 (full=false) | F7: screenshots/full/ 하위 .png 저장됨 (평문 시크릿 없음) | G7: safe | H7: auto | I7: PASS | L7: 2026-05-12 15:32:56 | M7: tools/ui_e2e/screenshots/full/AH_PROT_AdminKnowledgeBaseUpload.png

Sheet AdminRagMetrics
A1: ID | B1: 화면 | C1: 인터랙션 | D1: 사전조건 | E1: 입력/액션 | F1: 기대 결과 | G1: 위험도 | H1: 자동화 | I1: 결과 | J1: 실측값 | K1: 비고 | L1: 검증일시 | M1: 스크린샷 경로
A2: AH-027-01 | B2: AdminRagMetrics | C2: 화면 진입 (admin 세션) | D2: (admin 로그인) — public 라우트도 admin 세션 보유 상태에서 진입 | E2: GET /admin/rag-metrics | F2: HTTP 200 또는 클라이언트 라우팅 성공 + 페이지 마운트 (Vue/Next 컴포넌트 렌더) | G2: safe | H2: auto | I2: PASS | J2: DOM mounted=True | duration=1784ms | final=http://192.168.10.39:64005/admin/rag-metrics | L2: 2026-05-12 15:32:57 | M2: tools/ui_e2e/screenshots/full/AH_PROT_AdminRagMetrics.png
A3: AH-027-02 | B3: AdminRagMetrics | C3: 권한 분기 (anonymous → /login 리다이렉트) | D3: (미로그인 + 새 컨텍스트) | E3: GET /admin/rag-metrics (token 없음) | F3: /login?redirect=... 또는 /landing 으로 리다이렉트 | G3: safe | H3: auto | I3: PASS | J3: final=http://192.168.10.39:64005/login?redirect=/admin/rag-metrics | K3: final=http://192.168.10.39:64005/login?redirect=/admin/rag-metrics | L3: 2026-05-12 15:40:00
A4: AH-027-03 | B4: AdminRagMetrics | C4: DOM 마운트 + 주요 컨테이너 렌더 | D4: (라우트 진입 완료) | E4: DOM 로드 + 1초 대기 → console error 0건 + 핵심 selector 가시 | F4: console error 0건 (잘 알려진 외부 라이브러리 경고 제외), 핵심 컨테이너(main/main-layout/page-root) 렌더 | G4: safe | H4: auto | I4: PASS | L4: 2026-05-12 15:32:57
A5: AH-027-04 | B5: AdminRagMetrics | C5: 페이지 진입 시 API 자동 호출 응답 확인 | D5: (라우트 진입 완료) | E5: network 모니터 — 첫 5초 내 발생한 /api 또는 /v1 호출 + 상태코드 수집 | F5: 관련 API 200 OK 또는 비-401 응답. 401 발생 시 권한 분기 케이스로 분류 | G5: safe | H5: auto | I5: PASS | L5: 2026-05-12 15:32:57
A6: AH-027-05 | B6: AdminRagMetrics | C6: 사이드바 / 헤더 / 활성 메뉴 표시 | D6: (라우트 진입 완료) | E6: 선택된 메뉴 highlight + 현재 사용자(admin) 정보 표시 확인 | F6: 사이드바 노드 활성 클래스 + 사용자 아바타/이름 가시 | G6: safe | H6: auto | I6: PASS | L6: 2026-05-12 15:32:57
A7: AH-027-06 | B7: AdminRagMetrics | C7: 스크린샷 캡처 (감사용) | D7: (라우트 진입 + DOM 안정화) | E7: viewport 스크린샷 (full=false) | F7: screenshots/full/ 하위 .png 저장됨 (평문 시크릿 없음) | G7: safe | H7: auto | I7: PASS | L7: 2026-05-12 15:32:57 | M7: tools/ui_e2e/screenshots/full/AH_PROT_AdminRagMetrics.png
A8: AH-SP-041 | B8: RAG 메트릭 | C8: RAG 메트릭 차트 표시 | D8: (admin 로그인) | E8: /admin/rag-metrics 진입 | F8: 메트릭 차트/표 렌더 | G8: safe | H8: auto | I8: PASS | K8: [라이브 라우트 결과 인용] AdminRagMetrics: PASS | L8: 2026-05-12 (인용)

Sheet AgentBuilder
A1: ID | B1: 화면 | C1: 인터랙션 | D1: 사전조건 | E1: 입력/액션 | F1: 기대 결과 | G1: 위험도 | H1: 자동화 | I1: 결과 | J1: 실측값 | K1: 비고 | L1: 검증일시 | M1: 스크린샷 경로
A2: AH-015-01 | B2: AgentBuilder | C2: 화면 진입 (admin 세션) | D2: (admin 로그인) — public 라우트도 admin 세션 보유 상태에서 진입 | E2: GET /agents/builder | F2: HTTP 200 또는 클라이언트 라우팅 성공 + 페이지 마운트 (Vue/Next 컴포넌트 렌더) | G2: safe | H2: auto | I2: PASS | J2: DOM mounted=True | duration=1801ms | final=http://192.168.10.39:64005/agents/builder | L2: 2026-05-12 15:32:36 | M2: tools/ui_e2e/screenshots/full/AH_PROT_AgentBuilder.png
A3: AH-015-02 | B3: AgentBuilder | C3: 권한 분기 (anonymous → /login 리다이렉트) | D3: (미로그인 + 새 컨텍스트) | E3: GET /agents/builder (token 없음) | F3: /login?redirect=... 또는 /landing 으로 리다이렉트 | G3: safe | H3: auto | I3: PASS | J3: final=http://192.168.10.39:64005/login?redirect=/agents/builder | K3: final=http://192.168.10.39:64005/login?redirect=/agents/builder | L3: 2026-05-12 15:40:00
A4: AH-015-03 | B4: AgentBuilder | C4: DOM 마운트 + 주요 컨테이너 렌더 | D4: (라우트 진입 완료) | E4: DOM 로드 + 1초 대기 → console error 0건 + 핵심 selector 가시 | F4: console error 0건 (잘 알려진 외부 라이브러리 경고 제외), 핵심 컨테이너(main/main-layout/page-root) 렌더 | G4: safe | H4: auto | I4: PASS | L4: 2026-05-12 15:32:36
A5: AH-015-04 | B5: AgentBuilder | C5: 페이지 진입 시 API 자동 호출 응답 확인 | D5: (라우트 진입 완료) | E5: network 모니터 — 첫 5초 내 발생한 /api 또는 /v1 호출 + 상태코드 수집 | F5: 관련 API 200 OK 또는 비-401 응답. 401 발생 시 권한 분기 케이스로 분류 | G5: safe | H5: auto | I5: PASS | L5: 2026-05-12 15:32:36
A6: AH-015-05 | B6: AgentBuilder | C6: 사이드바 / 헤더 / 활성 메뉴 표시 | D6: (라우트 진입 완료) | E6: 선택된 메뉴 highlight + 현재 사용자(admin) 정보 표시 확인 | F6: 사이드바 노드 활성 클래스 + 사용자 아바타/이름 가시 | G6: safe | H6: auto | I6: PASS | L6: 2026-05-12 15:32:36
A7: AH-015-06 | B7: AgentBuilder | C7: 스크린샷 캡처 (감사용) | D7: (라우트 진입 + DOM 안정화) | E7: viewport 스크린샷 (full=false) | F7: screenshots/full/ 하위 .png 저장됨 (평문 시크릿 없음) | G7: safe | H7: auto | I7: PASS | L7: 2026-05-12 15:32:36 | M7: tools/ui_e2e/screenshots/full/AH_PROT_AgentBuilder.png
A8: AH-SP-032 | B8: 에이전트 빌더 | C8: 신규 에이전트 생성 폼 표시 | D8: (admin 로그인) | E8: /agents/builder 진입 | F8: 이름/모델/시스템 프롬프트 입력 필드 가시 | G8: safe | H8: auto | I8: PASS | K8: [라이브 라우트 결과 인용] AgentBuilder: PASS | L8: 2026-05-12 (인용)

Sheet AgentChat
A1: ID | B1: 화면 | C1: 인터랙션 | D1: 사전조건 | E1: 입력/액션 | F1: 기대 결과 | G1: 위험도 | H1: 자동화 | I1: 결과 | J1: 실측값 | K1: 비고 | L1: 검증일시 | M1: 스크린샷 경로
A2: AH-013-01 | B2: AgentChat | C2: 화면 진입 (admin 세션) | D2: (admin 로그인) — public 라우트도 admin 세션 보유 상태에서 진입 | E2: GET /agents/chat | F2: HTTP 200 또는 클라이언트 라우팅 성공 + 페이지 마운트 (Vue/Next 컴포넌트 렌더) | G2: safe | H2: auto | I2: PASS | J2: DOM mounted=True | duration=2727ms | final=http://192.168.10.39:64005/agents/chat | L2: 2026-05-12 15:32:31 | M2: tools/ui_e2e/screenshots/full/AH_PROT_AgentChat.png
A3: AH-013-02 | B3: AgentChat | C3: 권한 분기 (anonymous → /login 리다이렉트) | D3: (미로그인 + 새 컨텍스트) | E3: GET /agents/chat (token 없음) | F3: /login?redirect=... 또는 /landing 으로 리다이렉트 | G3: safe | H3: auto | I3: PASS | J3: final=http://192.168.10.39:64005/login?redirect=/agents/chat | K3: final=http://192.168.10.39:64005/login?redirect=/agents/chat | L3: 2026-05-12 15:40:00
A4: AH-013-03 | B4: AgentChat | C4: DOM 마운트 + 주요 컨테이너 렌더 | D4: (라우트 진입 완료) | E4: DOM 로드 + 1초 대기 → console error 0건 + 핵심 selector 가시 | F4: console error 0건 (잘 알려진 외부 라이브러리 경고 제외), 핵심 컨테이너(main/main-layout/page-root) 렌더 | G4: safe | H4: auto | I4: PASS | L4: 2026-05-12 15:32:31
A5: AH-013-04 | B5: AgentChat | C5: 페이지 진입 시 API 자동 호출 응답 확인 | D5: (라우트 진입 완료) | E5: network 모니터 — 첫 5초 내 발생한 /api 또는 /v1 호출 + 상태코드 수집 | F5: 관련 API 200 OK 또는 비-401 응답. 401 발생 시 권한 분기 케이스로 분류 | G5: safe | H5: auto | I5: PASS | L5: 2026-05-12 15:32:31
A6: AH-013-05 | B6: AgentChat | C6: 사이드바 / 헤더 / 활성 메뉴 표시 | D6: (라우트 진입 완료) | E6: 선택된 메뉴 highlight + 현재 사용자(admin) 정보 표시 확인 | F6: 사이드바 노드 활성 클래스 + 사용자 아바타/이름 가시 | G6: safe | H6: auto | I6: PASS | L6: 2026-05-12 15:32:31
A7: AH-013-06 | B7: AgentChat | C7: 스크린샷 캡처 (감사용) | D7: (라우트 진입 + DOM 안정화) | E7: viewport 스크린샷 (full=false) | F7: screenshots/full/ 하위 .png 저장됨 (평문 시크릿 없음) | G7: safe | H7: auto | I7: PASS | L7: 2026-05-12 15:32:31 | M7: tools/ui_e2e/screenshots/full/AH_PROT_AgentChat.png
A8: AH-SP-031 | B8: 에이전트 채팅 | C8: [시나리오 2 인용] LLM 1회 호출 | D8: 트랙 #75 commit b7de919 참조 | E8: (자동화 완료 — 재실행 안 함) | F8: PASS (시나리오 2 결과 인용 — LLM 비용 1회만) | G8: cost | H8: manual | I8: PASS | K8: [시나리오 2 인용] tools/ui_e2e/scenario_2_result.json (b7de919) | L8: 2026-05-12 (인용)

Sheet AgentEmbed
A1: ID | B1: 화면 | C1: 인터랙션 | D1: 사전조건 | E1: 입력/액션 | F1: 기대 결과 | G1: 위험도 | H1: 자동화 | I1: 결과 | J1: 실측값 | K1: 비고 | L1: 검증일시 | M1: 스크린샷 경로
A2: AH-008-01 | B2: AgentEmbed | C2: 화면 진입 (anonymous) | D2: (미로그인) anonymous | E2: GET /embed/test | F2: HTTP 200 또는 클라이언트 라우팅 성공 + 페이지 마운트 (Vue/Next 컴포넌트 렌더) | G2: safe | H2: auto | I2: PASS | J2: DOM mounted=True | duration=1770ms | final=http://192.168.10.39:64005/embed/test | net_issues=1: [{'url': 'http://192.168.10.39:64005/api/agents/public/test/info', 'status': 404}] | L2: 2026-05-12 15:32:21 | M2: tools/ui_e2e/screenshots/full/AH_PUB_AgentEmbed.png
A3: AH-008-02 | B3: AgentEmbed | C3: 권한 분기 (admin 진입도 허용) | D3: (admin 로그인 상태) | E3: GET /embed/test | F3: redirect=true 가 아닌 경우 그대로 표시 또는 routerGuard 에 따라 /로 이동 | G3: safe | H3: auto | I3: PASS | L3: 2026-05-12 15:32:21
A4: AH-008-03 | B4: AgentEmbed | C4: DOM 마운트 + 주요 컨테이너 렌더 | D4: (라우트 진입 완료) | E4: DOM 로드 + 1초 대기 → console error 0건 + 핵심 selector 가시 | F4: console error 0건 (잘 알려진 외부 라이브러리 경고 제외), 핵심 컨테이너(main/main-layout/page-root) 렌더 | G4: safe | H4: auto | I4: PASS | L4: 2026-05-12 15:32:21
A5: AH-008-06 | B5: AgentEmbed | C5: 스크린샷 캡처 (감사용) | D5: (라우트 진입 + DOM 안정화) | E5: viewport 스크린샷 (full=false) | F5: screenshots/full/ 하위 .png 저장됨 (평문 시크릿 없음) | G5: safe | H5: auto | I5: PASS | L5: 2026-05-12 15:32:21 | M5: tools/ui_e2e/screenshots/full/AH_PUB_AgentEmbed.png
A6: AH-SP-122 | B6: 임베드 | C6: 잘못된 code → 에러 표시 | D6: (미로그인) | E6: /embed/nonexistent 진입 | F6: 404 또는 에러 메시지 | G6: safe | H6: auto | I6: PASS | K6: [라이브 라우트 결과 인용] AgentEmbed: PASS | L6: 2026-05-12 (인용)

Sheet AgentMarketplace
A1: ID | B1: 화면 | C1: 인터랙션 | D1: 사전조건 | E1: 입력/액션 | F1: 기대 결과 | G1: 위험도 | H1: 자동화 | I1: 결과 | J1: 실측값 | K1: 비고 | L1: 검증일시 | M1: 스크린샷 경로
A2: AH-020-01 | B2: AgentMarketplace | C2: 화면 진입 (admin 세션) | D2: (admin 로그인) — public 라우트도 admin 세션 보유 상태에서 진입 | E2: GET /agents/marketplace | F2: HTTP 200 또는 클라이언트 라우팅 성공 + 페이지 마운트 (Vue/Next 컴포넌트 렌더) | G2: safe | H2: auto | I2: PASS | J2: DOM mounted=True | duration=1795ms | final=http://192.168.10.39:64005/agents/marketplace | L2: 2026-05-12 15:32:45 | M2: tools/ui_e2e/screenshots/full/AH_PROT_AgentMarketplace.png
A3: AH-020-02 | B3: AgentMarketplace | C3: 권한 분기 (anonymous → /login 리다이렉트) | D3: (미로그인 + 새 컨텍스트) | E3: GET /agents/marketplace (token 없음) | F3: /login?redirect=... 또는 /landing 으로 리다이렉트 | G3: safe | H3: auto | I3: PASS | J3: final=http://192.168.10.39:64005/login?redirect=/agents/marketplace | K3: final=http://192.168.10.39:64005/login?redirect=/agents/marketplace | L3: 2026-05-12 15:40:00
A4: AH-020-03 | B4: AgentMarketplace | C4: DOM 마운트 + 주요 컨테이너 렌더 | D4: (라우트 진입 완료) | E4: DOM 로드 + 1초 대기 → console error 0건 + 핵심 selector 가시 | F4: console error 0건 (잘 알려진 외부 라이브러리 경고 제외), 핵심 컨테이너(main/main-layout/page-root) 렌더 | G4: safe | H4: auto | I4: PASS | L4: 2026-05-12 15:32:45
A5: AH-020-04 | B5: AgentMarketplace | C5: 페이지 진입 시 API 자동 호출 응답 확인 | D5: (라우트 진입 완료) | E5: network 모니터 — 첫 5초 내 발생한 /api 또는 /v1 호출 + 상태코드 수집 | F5: 관련 API 200 OK 또는 비-401 응답. 401 발생 시 권한 분기 케이스로 분류 | G5: safe | H5: auto | I5: PASS | L5: 2026-05-12 15:32:45
A6: AH-020-05 | B6: AgentMarketplace | C6: 사이드바 / 헤더 / 활성 메뉴 표시 | D6: (라우트 진입 완료) | E6: 선택된 메뉴 highlight + 현재 사용자(admin) 정보 표시 확인 | F6: 사이드바 노드 활성 클래스 + 사용자 아바타/이름 가시 | G6: safe | H6: auto | I6: PASS | L6: 2026-05-12 15:32:45
A7: AH-020-06 | B7: AgentMarketplace | C7: 스크린샷 캡처 (감사용) | D7: (라우트 진입 + DOM 안정화) | E7: viewport 스크린샷 (full=false) | F7: screenshots/full/ 하위 .png 저장됨 (평문 시크릿 없음) | G7: safe | H7: auto | I7: PASS | L7: 2026-05-12 15:32:45 | M7: tools/ui_e2e/screenshots/full/AH_PROT_AgentMarketplace.png
A8: AH-SP-100 | B8: 에이전트 마켓플레이스 | C8: 마켓플레이스 카드 표시 | D8: (admin 로그인) | E8: /agents/marketplace 진입 | F8: 에이전트 카드 그리드 렌더 | G8: safe | H8: auto | I8: PASS | K8: [라이브 라우트 결과 인용] AgentMarketplace: PASS | L8: 2026-05-12 (인용)

Sheet AgentMultiChat
A1: ID | B1: 화면 | C1: 인터랙션 | D1: 사전조건 | E1: 입력/액션 | F1: 기대 결과 | G1: 위험도 | H1: 자동화 | I1: 결과 | J1: 실측값 | K1: 비고 | L1: 검증일시 | M1: 스크린샷 경로
A2: AH-014-01 | B2: AgentMultiChat | C2: 화면 진입 (admin 세션) | D2: (admin 로그인) — public 라우트도 admin 세션 보유 상태에서 진입 | E2: GET /agents/multi-chat | F2: HTTP 200 또는 클라이언트 라우팅 성공 + 페이지 마운트 (Vue/Next 컴포넌트 렌더) | G2: safe | H2: auto | I2: PASS | J2: DOM mounted=True | duration=1813ms | final=http://192.168.10.39:64005/agents/multi-chat | L2: 2026-05-12 15:32:34 | M2: tools/ui_e2e/screenshots/full/AH_PROT_AgentMultiChat.png
A3: AH-014-02 | B3: AgentMultiChat | C3: 권한 분기 (anonymous → /login 리다이렉트) | D3: (미로그인 + 새 컨텍스트) | E3: GET /agents/multi-chat (token 없음) | F3: /login?redirect=... 또는 /landing 으로 리다이렉트 | G3: safe | H3: auto | I3: PASS | J3: final=http://192.168.10.39:64005/login?redirect=/agents/multi-chat | K3: final=http://192.168.10.39:64005/login?redirect=/agents/multi-chat | L3: 2026-05-12 15:40:00
A4: AH-014-03 | B4: AgentMultiChat | C4: DOM 마운트 + 주요 컨테이너 렌더 | D4: (라우트 진입 완료) | E4: DOM 로드 + 1초 대기 → console error 0건 + 핵심 selector 가시 | F4: console error 0건 (잘 알려진 외부 라이브러리 경고 제외), 핵심 컨테이너(main/main-layout/page-root) 렌더 | G4: safe | H4: auto | I4: PASS | L4: 2026-05-12 15:32:34
A5: AH-014-04 | B5: AgentMultiChat | C5: 페이지 진입 시 API 자동 호출 응답 확인 | D5: (라우트 진입 완료) | E5: network 모니터 — 첫 5초 내 발생한 /api 또는 /v1 호출 + 상태코드 수집 | F5: 관련 API 200 OK 또는 비-401 응답. 401 발생 시 권한 분기 케이스로 분류 | G5: safe | H5: auto | I5: PASS | L5: 2026-05-12 15:32:34
A6: AH-014-05 | B6: AgentMultiChat | C6: 사이드바 / 헤더 / 활성 메뉴 표시 | D6: (라우트 진입 완료) | E6: 선택된 메뉴 highlight + 현재 사용자(admin) 정보 표시 확인 | F6: 사이드바 노드 활성 클래스 + 사용자 아바타/이름 가시 | G6: safe | H6: auto | I6: PASS | L6: 2026-05-12 15:32:34
A7: AH-014-06 | B7: AgentMultiChat | C7: 스크린샷 캡처 (감사용) | D7: (라우트 진입 + DOM 안정화) | E7: viewport 스크린샷 (full=false) | F7: screenshots/full/ 하위 .png 저장됨 (평문 시크릿 없음) | G7: safe | H7: auto | I7: PASS | L7: 2026-05-12 15:32:34 | M7: tools/ui_e2e/screenshots/full/AH_PROT_AgentMultiChat.png
A8: AH-SP-120 | B8: 다중 에이전트 채팅 | C8: 다중 채팅 UI 마운트 | D8: (admin 로그인) | E8: /agents/multi-chat 진입 | F8: 다중 패널 UI 가시 | G8: safe | H8: auto | I8: PASS | K8: [라이브 라우트 결과 인용] AgentMultiChat: PASS | L8: 2026-05-12 (인용)

Sheet AgentPublicChat
A1: ID | B1: 화면 | C1: 인터랙션 | D1: 사전조건 | E1: 입력/액션 | F1: 기대 결과 | G1: 위험도 | H1: 자동화 | I1: 결과 | J1: 실측값 | K1: 비고 | L1: 검증일시 | M1: 스크린샷 경로
A2: AH-007-01 | B2: AgentPublicChat | C2: 화면 진입 (anonymous) | D2: (미로그인) anonymous | E2: GET /chatbot/test | F2: HTTP 200 또는 클라이언트 라우팅 성공 + 페이지 마운트 (Vue/Next 컴포넌트 렌더) | G2: safe | H2: auto | I2: PASS | J2: DOM mounted=True | duration=1773ms | final=http://192.168.10.39:64005/chatbot/test | net_issues=1: [{'url': 'http://192.168.10.39:64005/api/agents/public/test/info', 'status': 404}] | L2: 2026-05-12 15:32:20 | M2: tools/ui_e2e/screenshots/full/AH_PUB_AgentPublicChat.png
A3: AH-007-02 | B3: AgentPublicChat | C3: 권한 분기 (admin 진입도 허용) | D3: (admin 로그인 상태) | E3: GET /chatbot/test | F3: redirect=true 가 아닌 경우 그대로 표시 또는 routerGuard 에 따라 /로 이동 | G3: safe | H3: auto | I3: PASS | L3: 2026-05-12 15:32:20
A4: AH-007-03 | B4: AgentPublicChat | C4: DOM 마운트 + 주요 컨테이너 렌더 | D4: (라우트 진입 완료) | E4: DOM 로드 + 1초 대기 → console error 0건 + 핵심 selector 가시 | F4: console error 0건 (잘 알려진 외부 라이브러리 경고 제외), 핵심 컨테이너(main/main-layout/page-root) 렌더 | G4: safe | H4: auto | I4: PASS | L4: 2026-05-12 15:32:20
A5: AH-007-06 | B5: AgentPublicChat | C5: 스크린샷 캡처 (감사용) | D5: (라우트 진입 + DOM 안정화) | E5: viewport 스크린샷 (full=false) | F5: screenshots/full/ 하위 .png 저장됨 (평문 시크릿 없음) | G5: safe | H5: auto | I5: PASS | L5: 2026-05-12 15:32:20 | M5: tools/ui_e2e/screenshots/full/AH_PUB_AgentPublicChat.png
A6: AH-SP-121 | B6: 공개 챗봇 | C6: 잘못된 code → 404 또는 한국어 에러 | D6: (미로그인) | E6: /chatbot/nonexistent 진입 | F6: 404 페이지 또는 '에이전트를 찾을 수 없습니다' 메시지 | G6: safe | H6: auto | I6: PASS | K6: [라이브 라우트 결과 인용] AgentPublicChat: PASS | L6: 2026-05-12 (인용)

Sheet AgentTemplates
A1: ID | B1: 화면 | C1: 인터랙션 | D1: 사전조건 | E1: 입력/액션 | F1: 기대 결과 | G1: 위험도 | H1: 자동화 | I1: 결과 | J1: 실측값 | K1: 비고 | L1: 검증일시 | M1: 스크린샷 경로
A2: AH-021-01 | B2: AgentTemplates | C2: 화면 진입 (admin 세션) | D2: (admin 로그인) — public 라우트도 admin 세션 보유 상태에서 진입 | E2: GET /agents/templates | F2: HTTP 200 또는 클라이언트 라우팅 성공 + 페이지 마운트 (Vue/Next 컴포넌트 렌더) | G2: safe | H2: auto | I2: PASS | J2: DOM mounted=True | duration=1786ms | final=http://192.168.10.39:64005/agents/templates | L2: 2026-05-12 15:32:46 | M2: tools/ui_e2e/screenshots/full/AH_PROT_AgentTemplates.png
A3: AH-021-02 | B3: AgentTemplates | C3: 권한 분기 (anonymous → /login 리다이렉트) | D3: (미로그인 + 새 컨텍스트) | E3: GET /agents/templates (token 없음) | F3: /login?redirect=... 또는 /landing 으로 리다이렉트 | G3: safe | H3: auto | I3: PASS | J3: final=http://192.168.10.39:64005/login?redirect=/agents/templates | K3: final=http://192.168.10.39:64005/login?redirect=/agents/templates | L3: 2026-05-12 15:40:00
A4: AH-021-03 | B4: AgentTemplates | C4: DOM 마운트 + 주요 컨테이너 렌더 | D4: (라우트 진입 완료) | E4: DOM 로드 + 1초 대기 → console error 0건 + 핵심 selector 가시 | F4: console error 0건 (잘 알려진 외부 라이브러리 경고 제외), 핵심 컨테이너(main/main-layout/page-root) 렌더 | G4: safe | H4: auto | I4: PASS | L4: 2026-05-12 15:32:46
A5: AH-021-04 | B5: AgentTemplates | C5: 페이지 진입 시 API 자동 호출 응답 확인 | D5: (라우트 진입 완료) | E5: network 모니터 — 첫 5초 내 발생한 /api 또는 /v1 호출 + 상태코드 수집 | F5: 관련 API 200 OK 또는 비-401 응답. 401 발생 시 권한 분기 케이스로 분류 | G5: safe | H5: auto | I5: PASS | L5: 2026-05-12 15:32:46
